
2023-08-21 20:11:02.456241+00:00
<QuerySet [<ProfileClient: P1 Enesa - felipe.barraza.vega@gmail.com>]>
2023-08-21 20:12:02.323357+00:00
<QuerySet [<ProfileClient: P1 Enesa - felipe.barraza.vega@gmail.com>]>
2023-08-21 20:13:03.009789+00:00
<QuerySet [<ProfileClient: P1 Enesa - felipe.barraza.vega@gmail.com>]>
2023-08-21 20:14:02.680828+00:00
<QuerySet [<ProfileClient: P1 Enesa - felipe.barraza.vega@gmail.com>]>
2023-08-21 20:15:02.667636+00:00
<QuerySet [<ProfileClient: P1 Enesa - felipe.barraza.vega@gmail.com>]>
2023-08-21 20:16:02.546787+00:00
<QuerySet [<ProfileClient: P1 Enesa - felipe.barraza.vega@gmail.com>]>
2023-08-21 20:17:02.329829+00:00
<QuerySet [<ProfileClient: P1 Enesa - felipe.barraza.vega@gmail.com>]>
2023-08-21 20:18:02.350631+00:00
<QuerySet [<ProfileClient: P1 Enesa - felipe.barraza.vega@gmail.com>]>
2023-08-21 20:19:02.387903+00:00
<QuerySet [<ProfileClient: P1 Enesa - felipe.barraza.vega@gmail.com>]>
2023-08-21 20:20:02.547787+00:00
<QuerySet [<ProfileClient: P1 Enesa - felipe.barraza.vega@gmail.com>]>
2023-08-21 20:21:03.028787+00:00
<QuerySet [<ProfileClient: P1 Enesa - felipe.barraza.vega@gmail.com>]>
2023-08-21 20:22:02.872492+00:00
<QuerySet [<ProfileClient: P1 Enesa - felipe.barraza.vega@gmail.com>]>
2023-08-21 20:23:02.719014+00:00
<QuerySet [<ProfileClient: P1 Enesa - felipe.barraza.vega@gmail.com>]>
2023-08-21 20:24:03.241273+00:00
<QuerySet [<ProfileClient: P1 Enesa - felipe.barraza.vega@gmail.com>]>
2023-08-21 20:25:02.865792+00:00
<QuerySet [<ProfileClient: P1 Enesa - felipe.barraza.vega@gmail.com>]>
2023-08-21 20:26:02.904064+00:00
<QuerySet [<ProfileClient: P1 Enesa - felipe.barraza.vega@gmail.com>]>
2023-08-21 20:27:02.467623+00:00
<QuerySet [<ProfileClient: P1 Enesa - felipe.barraza.vega@gmail.com>]>
2023-08-21 20:28:03.035842+00:00
<QuerySet [<ProfileClient: P1 Enesa - felipe.barraza.vega@gmail.com>]>
2023-08-21 20:29:02.595006+00:00
<QuerySet [<ProfileClient: P1 Enesa - felipe.barraza.vega@gmail.com>]>
2023-08-21 20:30:02.511697+00:00
<QuerySet [<ProfileClient: P1 Enesa - felipe.barraza.vega@gmail.com>]>
2023-08-21 20:31:02.636148+00:00
<QuerySet [<ProfileClient: P1 Enesa - felipe.barraza.vega@gmail.com>]>
2023-08-21 20:32:02.669314+00:00
<QuerySet [<ProfileClient: P1 Enesa - felipe.barraza.vega@gmail.com>]>
2023-08-21 20:33:02.968402+00:00
<QuerySet [<ProfileClient: P1 Enesa - felipe.barraza.vega@gmail.com>]>
2023-08-21 20:34:03.232731+00:00
<QuerySet [<ProfileClient: P1 Enesa - felipe.barraza.vega@gmail.com>]>
2023-08-21 20:35:02.694531+00:00
<QuerySet [<ProfileClient: P1 Enesa - felipe.barraza.vega@gmail.com>]>
2023-08-21 20:36:02.278604+00:00
<QuerySet [<ProfileClient: P1 Enesa - felipe.barraza.vega@gmail.com>]>
2023-08-21 20:37:03.075099+00:00
<QuerySet [<ProfileClient: P1 Enesa - felipe.barraza.vega@gmail.com>]>
2023-08-21 20:38:02.176137+00:00
<QuerySet [<ProfileClient: P1 Enesa - felipe.barraza.vega@gmail.com>]>
2023-08-21 20:39:02.294450+00:00
<QuerySet [<ProfileClient: P1 Enesa - felipe.barraza.vega@gmail.com>]>
2023-08-21 20:40:02.706818+00:00
<QuerySet [<ProfileClient: P1 Enesa - felipe.barraza.vega@gmail.com>]>
2023-08-21 20:41:02.534740+00:00
<QuerySet [<ProfileClient: P1 Enesa - felipe.barraza.vega@gmail.com>]>
2023-08-21 20:42:02.146655+00:00
<QuerySet [<ProfileClient: P1 Enesa - felipe.barraza.vega@gmail.com>]>
2023-08-21 20:43:02.185020+00:00
<QuerySet [<ProfileClient: P1 Enesa - felipe.barraza.vega@gmail.com>]>
2023-08-21 20:44:02.401013+00:00
<QuerySet [<ProfileClient: P1 Enesa - felipe.barraza.vega@gmail.com>]>
2023-08-21 20:45:02.102248+00:00
<QuerySet [<ProfileClient: P1 Enesa - felipe.barraza.vega@gmail.com>]>
2023-08-21 20:46:02.727218+00:00
<QuerySet [<ProfileClient: P1 Enesa - felipe.barraza.vega@gmail.com>]>
Traceback (most recent call last):
  File "/code/manage.py", line 21, in <module>
    main()
  File "/code/manage.py", line 17, in main
    execute_from_command_line(sys.argv)
  File "/usr/local/lib/python3.11/site-packages/django/core/management/__init__.py", line 442, in execute_from_command_line
    utility.execute()
  File "/usr/local/lib/python3.11/site-packages/django/core/management/__init__.py", line 436, in execute
    self.fetch_command(subcommand).run_from_argv(self.argv)
  File "/usr/local/lib/python3.11/site-packages/django/core/management/base.py", line 412, in run_from_argv
    self.execute(*args, **cmd_options)
  File "/usr/local/lib/python3.11/site-packages/django/core/management/base.py", line 458, in execute
    output = self.handle(*args, **options)
             ^^^^^^^^^^^^^^^^^^^^^^^^^^^^^
  File "/usr/local/lib/python3.11/site-packages/django_crontab/management/commands/crontab.py", line 29, in handle
    Crontab().run_job(options['jobhash'])
  File "/usr/local/lib/python3.11/site-packages/django_crontab/crontab.py", line 126, in run_job
    job = self.__get_job_by_hash(job_hash)
          ^^^^^^^^^^^^^^^^^^^^^^^^^^^^^^^^
  File "/usr/local/lib/python3.11/site-packages/django_crontab/crontab.py", line 171, in __get_job_by_hash
    raise RuntimeError(
RuntimeError: No job with hash ec5dbe1e3d5dc442218eaf99df363c83 found. It seems the crontab is out of sync with your settings.CRONJOBS. Run "python manage.py crontab add" again to resolve this issue!
Traceback (most recent call last):
  File "/code/manage.py", line 21, in <module>
    main()
  File "/code/manage.py", line 17, in main
    execute_from_command_line(sys.argv)
  File "/usr/local/lib/python3.11/site-packages/django/core/management/__init__.py", line 442, in execute_from_command_line
    utility.execute()
  File "/usr/local/lib/python3.11/site-packages/django/core/management/__init__.py", line 436, in execute
    self.fetch_command(subcommand).run_from_argv(self.argv)
  File "/usr/local/lib/python3.11/site-packages/django/core/management/base.py", line 412, in run_from_argv
    self.execute(*args, **cmd_options)
  File "/usr/local/lib/python3.11/site-packages/django/core/management/base.py", line 458, in execute
    output = self.handle(*args, **options)
             ^^^^^^^^^^^^^^^^^^^^^^^^^^^^^
  File "/usr/local/lib/python3.11/site-packages/django_crontab/management/commands/crontab.py", line 29, in handle
    Crontab().run_job(options['jobhash'])
  File "/usr/local/lib/python3.11/site-packages/django_crontab/crontab.py", line 126, in run_job
    job = self.__get_job_by_hash(job_hash)
          ^^^^^^^^^^^^^^^^^^^^^^^^^^^^^^^^
  File "/usr/local/lib/python3.11/site-packages/django_crontab/crontab.py", line 171, in __get_job_by_hash
    raise RuntimeError(
RuntimeError: No job with hash ec5dbe1e3d5dc442218eaf99df363c83 found. It seems the crontab is out of sync with your settings.CRONJOBS. Run "python manage.py crontab add" again to resolve this issue!
Traceback (most recent call last):
  File "/code/manage.py", line 21, in <module>
    main()
  File "/code/manage.py", line 17, in main
    execute_from_command_line(sys.argv)
  File "/usr/local/lib/python3.11/site-packages/django/core/management/__init__.py", line 442, in execute_from_command_line
    utility.execute()
  File "/usr/local/lib/python3.11/site-packages/django/core/management/__init__.py", line 436, in execute
    self.fetch_command(subcommand).run_from_argv(self.argv)
  File "/usr/local/lib/python3.11/site-packages/django/core/management/base.py", line 412, in run_from_argv
    self.execute(*args, **cmd_options)
  File "/usr/local/lib/python3.11/site-packages/django/core/management/base.py", line 458, in execute
    output = self.handle(*args, **options)
             ^^^^^^^^^^^^^^^^^^^^^^^^^^^^^
  File "/usr/local/lib/python3.11/site-packages/django_crontab/management/commands/crontab.py", line 29, in handle
    Crontab().run_job(options['jobhash'])
  File "/usr/local/lib/python3.11/site-packages/django_crontab/crontab.py", line 126, in run_job
    job = self.__get_job_by_hash(job_hash)
          ^^^^^^^^^^^^^^^^^^^^^^^^^^^^^^^^
  File "/usr/local/lib/python3.11/site-packages/django_crontab/crontab.py", line 171, in __get_job_by_hash
    raise RuntimeError(
RuntimeError: No job with hash ec5dbe1e3d5dc442218eaf99df363c83 found. It seems the crontab is out of sync with your settings.CRONJOBS. Run "python manage.py crontab add" again to resolve this issue!
Traceback (most recent call last):
  File "/code/manage.py", line 21, in <module>
    main()
  File "/code/manage.py", line 17, in main
    execute_from_command_line(sys.argv)
  File "/usr/local/lib/python3.11/site-packages/django/core/management/__init__.py", line 442, in execute_from_command_line
    utility.execute()
  File "/usr/local/lib/python3.11/site-packages/django/core/management/__init__.py", line 436, in execute
    self.fetch_command(subcommand).run_from_argv(self.argv)
  File "/usr/local/lib/python3.11/site-packages/django/core/management/base.py", line 412, in run_from_argv
    self.execute(*args, **cmd_options)
  File "/usr/local/lib/python3.11/site-packages/django/core/management/base.py", line 458, in execute
    output = self.handle(*args, **options)
             ^^^^^^^^^^^^^^^^^^^^^^^^^^^^^
  File "/usr/local/lib/python3.11/site-packages/django_crontab/management/commands/crontab.py", line 29, in handle
    Crontab().run_job(options['jobhash'])
  File "/usr/local/lib/python3.11/site-packages/django_crontab/crontab.py", line 126, in run_job
    job = self.__get_job_by_hash(job_hash)
          ^^^^^^^^^^^^^^^^^^^^^^^^^^^^^^^^
  File "/usr/local/lib/python3.11/site-packages/django_crontab/crontab.py", line 171, in __get_job_by_hash
    raise RuntimeError(
RuntimeError: No job with hash ec5dbe1e3d5dc442218eaf99df363c83 found. It seems the crontab is out of sync with your settings.CRONJOBS. Run "python manage.py crontab add" again to resolve this issue!
Traceback (most recent call last):
  File "/code/manage.py", line 21, in <module>
    main()
  File "/code/manage.py", line 17, in main
    execute_from_command_line(sys.argv)
  File "/usr/local/lib/python3.11/site-packages/django/core/management/__init__.py", line 442, in execute_from_command_line
    utility.execute()
  File "/usr/local/lib/python3.11/site-packages/django/core/management/__init__.py", line 436, in execute
    self.fetch_command(subcommand).run_from_argv(self.argv)
  File "/usr/local/lib/python3.11/site-packages/django/core/management/base.py", line 412, in run_from_argv
    self.execute(*args, **cmd_options)
  File "/usr/local/lib/python3.11/site-packages/django/core/management/base.py", line 458, in execute
    output = self.handle(*args, **options)
             ^^^^^^^^^^^^^^^^^^^^^^^^^^^^^
  File "/usr/local/lib/python3.11/site-packages/django_crontab/management/commands/crontab.py", line 29, in handle
    Crontab().run_job(options['jobhash'])
  File "/usr/local/lib/python3.11/site-packages/django_crontab/crontab.py", line 126, in run_job
    job = self.__get_job_by_hash(job_hash)
          ^^^^^^^^^^^^^^^^^^^^^^^^^^^^^^^^
  File "/usr/local/lib/python3.11/site-packages/django_crontab/crontab.py", line 171, in __get_job_by_hash
    raise RuntimeError(
RuntimeError: No job with hash ec5dbe1e3d5dc442218eaf99df363c83 found. It seems the crontab is out of sync with your settings.CRONJOBS. Run "python manage.py crontab add" again to resolve this issue!
Traceback (most recent call last):
  File "/code/manage.py", line 21, in <module>
    main()
  File "/code/manage.py", line 17, in main
    execute_from_command_line(sys.argv)
  File "/usr/local/lib/python3.11/site-packages/django/core/management/__init__.py", line 442, in execute_from_command_line
    utility.execute()
  File "/usr/local/lib/python3.11/site-packages/django/core/management/__init__.py", line 436, in execute
    self.fetch_command(subcommand).run_from_argv(self.argv)
  File "/usr/local/lib/python3.11/site-packages/django/core/management/base.py", line 412, in run_from_argv
    self.execute(*args, **cmd_options)
  File "/usr/local/lib/python3.11/site-packages/django/core/management/base.py", line 458, in execute
    output = self.handle(*args, **options)
             ^^^^^^^^^^^^^^^^^^^^^^^^^^^^^
  File "/usr/local/lib/python3.11/site-packages/django_crontab/management/commands/crontab.py", line 29, in handle
    Crontab().run_job(options['jobhash'])
  File "/usr/local/lib/python3.11/site-packages/django_crontab/crontab.py", line 126, in run_job
    job = self.__get_job_by_hash(job_hash)
          ^^^^^^^^^^^^^^^^^^^^^^^^^^^^^^^^
  File "/usr/local/lib/python3.11/site-packages/django_crontab/crontab.py", line 171, in __get_job_by_hash
    raise RuntimeError(
RuntimeError: No job with hash ec5dbe1e3d5dc442218eaf99df363c83 found. It seems the crontab is out of sync with your settings.CRONJOBS. Run "python manage.py crontab add" again to resolve this issue!
Traceback (most recent call last):
  File "/code/manage.py", line 21, in <module>
    main()
  File "/code/manage.py", line 17, in main
    execute_from_command_line(sys.argv)
  File "/usr/local/lib/python3.11/site-packages/django/core/management/__init__.py", line 442, in execute_from_command_line
    utility.execute()
  File "/usr/local/lib/python3.11/site-packages/django/core/management/__init__.py", line 436, in execute
    self.fetch_command(subcommand).run_from_argv(self.argv)
  File "/usr/local/lib/python3.11/site-packages/django/core/management/base.py", line 412, in run_from_argv
    self.execute(*args, **cmd_options)
  File "/usr/local/lib/python3.11/site-packages/django/core/management/base.py", line 458, in execute
    output = self.handle(*args, **options)
             ^^^^^^^^^^^^^^^^^^^^^^^^^^^^^
  File "/usr/local/lib/python3.11/site-packages/django_crontab/management/commands/crontab.py", line 29, in handle
    Crontab().run_job(options['jobhash'])
  File "/usr/local/lib/python3.11/site-packages/django_crontab/crontab.py", line 126, in run_job
    job = self.__get_job_by_hash(job_hash)
          ^^^^^^^^^^^^^^^^^^^^^^^^^^^^^^^^
  File "/usr/local/lib/python3.11/site-packages/django_crontab/crontab.py", line 171, in __get_job_by_hash
    raise RuntimeError(
RuntimeError: No job with hash ec5dbe1e3d5dc442218eaf99df363c83 found. It seems the crontab is out of sync with your settings.CRONJOBS. Run "python manage.py crontab add" again to resolve this issue!
Traceback (most recent call last):
  File "/code/manage.py", line 21, in <module>
    main()
  File "/code/manage.py", line 17, in main
    execute_from_command_line(sys.argv)
  File "/usr/local/lib/python3.11/site-packages/django/core/management/__init__.py", line 442, in execute_from_command_line
    utility.execute()
  File "/usr/local/lib/python3.11/site-packages/django/core/management/__init__.py", line 436, in execute
    self.fetch_command(subcommand).run_from_argv(self.argv)
  File "/usr/local/lib/python3.11/site-packages/django/core/management/base.py", line 412, in run_from_argv
    self.execute(*args, **cmd_options)
  File "/usr/local/lib/python3.11/site-packages/django/core/management/base.py", line 458, in execute
    output = self.handle(*args, **options)
             ^^^^^^^^^^^^^^^^^^^^^^^^^^^^^
  File "/usr/local/lib/python3.11/site-packages/django_crontab/management/commands/crontab.py", line 29, in handle
    Crontab().run_job(options['jobhash'])
  File "/usr/local/lib/python3.11/site-packages/django_crontab/crontab.py", line 126, in run_job
    job = self.__get_job_by_hash(job_hash)
          ^^^^^^^^^^^^^^^^^^^^^^^^^^^^^^^^
  File "/usr/local/lib/python3.11/site-packages/django_crontab/crontab.py", line 171, in __get_job_by_hash
    raise RuntimeError(
RuntimeError: No job with hash ec5dbe1e3d5dc442218eaf99df363c83 found. It seems the crontab is out of sync with your settings.CRONJOBS. Run "python manage.py crontab add" again to resolve this issue!
Traceback (most recent call last):
  File "/code/manage.py", line 21, in <module>
    main()
  File "/code/manage.py", line 17, in main
    execute_from_command_line(sys.argv)
  File "/usr/local/lib/python3.11/site-packages/django/core/management/__init__.py", line 442, in execute_from_command_line
    utility.execute()
  File "/usr/local/lib/python3.11/site-packages/django/core/management/__init__.py", line 436, in execute
    self.fetch_command(subcommand).run_from_argv(self.argv)
  File "/usr/local/lib/python3.11/site-packages/django/core/management/base.py", line 412, in run_from_argv
    self.execute(*args, **cmd_options)
  File "/usr/local/lib/python3.11/site-packages/django/core/management/base.py", line 458, in execute
    output = self.handle(*args, **options)
             ^^^^^^^^^^^^^^^^^^^^^^^^^^^^^
  File "/usr/local/lib/python3.11/site-packages/django_crontab/management/commands/crontab.py", line 29, in handle
    Crontab().run_job(options['jobhash'])
  File "/usr/local/lib/python3.11/site-packages/django_crontab/crontab.py", line 126, in run_job
    job = self.__get_job_by_hash(job_hash)
          ^^^^^^^^^^^^^^^^^^^^^^^^^^^^^^^^
  File "/usr/local/lib/python3.11/site-packages/django_crontab/crontab.py", line 171, in __get_job_by_hash
    raise RuntimeError(
RuntimeError: No job with hash ec5dbe1e3d5dc442218eaf99df363c83 found. It seems the crontab is out of sync with your settings.CRONJOBS. Run "python manage.py crontab add" again to resolve this issue!
Traceback (most recent call last):
  File "/code/manage.py", line 21, in <module>
    main()
  File "/code/manage.py", line 17, in main
    execute_from_command_line(sys.argv)
  File "/usr/local/lib/python3.11/site-packages/django/core/management/__init__.py", line 442, in execute_from_command_line
    utility.execute()
  File "/usr/local/lib/python3.11/site-packages/django/core/management/__init__.py", line 436, in execute
    self.fetch_command(subcommand).run_from_argv(self.argv)
  File "/usr/local/lib/python3.11/site-packages/django/core/management/base.py", line 412, in run_from_argv
    self.execute(*args, **cmd_options)
  File "/usr/local/lib/python3.11/site-packages/django/core/management/base.py", line 458, in execute
    output = self.handle(*args, **options)
             ^^^^^^^^^^^^^^^^^^^^^^^^^^^^^
  File "/usr/local/lib/python3.11/site-packages/django_crontab/management/commands/crontab.py", line 29, in handle
    Crontab().run_job(options['jobhash'])
  File "/usr/local/lib/python3.11/site-packages/django_crontab/crontab.py", line 126, in run_job
    job = self.__get_job_by_hash(job_hash)
          ^^^^^^^^^^^^^^^^^^^^^^^^^^^^^^^^
  File "/usr/local/lib/python3.11/site-packages/django_crontab/crontab.py", line 171, in __get_job_by_hash
    raise RuntimeError(
RuntimeError: No job with hash ec5dbe1e3d5dc442218eaf99df363c83 found. It seems the crontab is out of sync with your settings.CRONJOBS. Run "python manage.py crontab add" again to resolve this issue!
