Failed to complete cronjob at ('0 * * * *', 'api.crm.cron.main', '>> /code/api/log/debug7.log 2>&1 ')
Traceback (most recent call last):
  File "/usr/local/lib/python3.10/site-packages/urllib3/connection.py", line 203, in _new_conn
    sock = connection.create_connection(
  File "/usr/local/lib/python3.10/site-packages/urllib3/util/connection.py", line 60, in create_connection
    for res in socket.getaddrinfo(host, port, family, socket.SOCK_STREAM):
  File "/usr/local/lib/python3.10/socket.py", line 955, in getaddrinfo
    for res in _socket.getaddrinfo(host, port, family, type, proto, flags):
socket.gaierror: [Errno -3] Temporary failure in name resolution

The above exception was the direct cause of the following exception:

Traceback (most recent call last):
  File "/usr/local/lib/python3.10/site-packages/urllib3/connectionpool.py", line 790, in urlopen
    response = self._make_request(
  File "/usr/local/lib/python3.10/site-packages/urllib3/connectionpool.py", line 491, in _make_request
    raise new_e
  File "/usr/local/lib/python3.10/site-packages/urllib3/connectionpool.py", line 467, in _make_request
    self._validate_conn(conn)
  File "/usr/local/lib/python3.10/site-packages/urllib3/connectionpool.py", line 1092, in _validate_conn
    conn.connect()
  File "/usr/local/lib/python3.10/site-packages/urllib3/connection.py", line 611, in connect
    self.sock = sock = self._new_conn()
  File "/usr/local/lib/python3.10/site-packages/urllib3/connection.py", line 210, in _new_conn
    raise NameResolutionError(self.host, self, e) from e
urllib3.exceptions.NameResolutionError: <urllib3.connection.HTTPSConnection object at 0x7fe169b1f3d0>: Failed to resolve 'api.thethings.io' ([Errno -3] Temporary failure in name resolution)

The above exception was the direct cause of the following exception:

Traceback (most recent call last):
  File "/usr/local/lib/python3.10/site-packages/requests/adapters.py", line 486, in send
    resp = conn.urlopen(
  File "/usr/local/lib/python3.10/site-packages/urllib3/connectionpool.py", line 844, in urlopen
    retries = retries.increment(
  File "/usr/local/lib/python3.10/site-packages/urllib3/util/retry.py", line 515, in increment
    raise MaxRetryError(_pool, url, reason) from reason  # type: ignore[arg-type]
urllib3.exceptions.MaxRetryError: HTTPSConnectionPool(host='api.thethings.io', port=443): Max retries exceeded with url: /v2/things/LMgiBGLyCipU1ksf51FHRrAMB82VZzY_BoXyWkyA6F0/resources/volacum_p5/?limit=1 (Caused by NameResolutionError("<urllib3.connection.HTTPSConnection object at 0x7fe169b1f3d0>: Failed to resolve 'api.thethings.io' ([Errno -3] Temporary failure in name resolution)"))

During handling of the above exception, another exception occurred:

Traceback (most recent call last):
  File "/usr/local/lib/python3.10/site-packages/django_crontab/crontab.py", line 145, in run_job
    func(*job_args, **job_kwargs)
  File "/code/api/crm/cron.py", line 131, in main
    get_novus_and_save_in_api()
  File "/code/api/crm/cron.py", line 44, in get_novus_and_save_in_api
    request = requests.get(parsed_url)
  File "/usr/local/lib/python3.10/site-packages/requests/api.py", line 73, in get
    return request("get", url, params=params, **kwargs)
  File "/usr/local/lib/python3.10/site-packages/requests/api.py", line 59, in request
    return session.request(method=method, url=url, **kwargs)
  File "/usr/local/lib/python3.10/site-packages/requests/sessions.py", line 589, in request
    resp = self.send(prep, **send_kwargs)
  File "/usr/local/lib/python3.10/site-packages/requests/sessions.py", line 703, in send
    r = adapter.send(request, **kwargs)
  File "/usr/local/lib/python3.10/site-packages/requests/adapters.py", line 519, in send
    raise ConnectionError(e, request=request)
requests.exceptions.ConnectionError: HTTPSConnectionPool(host='api.thethings.io', port=443): Max retries exceeded with url: /v2/things/LMgiBGLyCipU1ksf51FHRrAMB82VZzY_BoXyWkyA6F0/resources/volacum_p5/?limit=1 (Caused by NameResolutionError("<urllib3.connection.HTTPSConnection object at 0x7fe169b1f3d0>: Failed to resolve 'api.thethings.io' ([Errno -3] Temporary failure in name resolution)"))
Failed to complete cronjob at ('0 * * * *', 'api.crm.cron.main', '>> /code/api/log/debug7.log 2>&1 ')
Traceback (most recent call last):
  File "/usr/local/lib/python3.10/site-packages/django/db/backends/utils.py", line 89, in _execute
    return self.cursor.execute(sql, params)
psycopg2.OperationalError: server closed the connection unexpectedly
	This probably means the server terminated abnormally
	before or while processing the request.


The above exception was the direct cause of the following exception:

Traceback (most recent call last):
  File "/usr/local/lib/python3.10/site-packages/django_crontab/crontab.py", line 145, in run_job
    func(*job_args, **job_kwargs)
  File "/code/api/crm/cron.py", line 131, in main
    get_novus_and_save_in_api()
  File "/code/api/crm/cron.py", line 126, in get_novus_and_save_in_api
    serializer.is_valid(raise_exception=True)
  File "/usr/local/lib/python3.10/site-packages/rest_framework/serializers.py", line 227, in is_valid
    self._validated_data = self.run_validation(self.initial_data)
  File "/usr/local/lib/python3.10/site-packages/rest_framework/serializers.py", line 426, in run_validation
    value = self.to_internal_value(data)
  File "/usr/local/lib/python3.10/site-packages/rest_framework/serializers.py", line 483, in to_internal_value
    validated_value = field.run_validation(primitive_value)
  File "/usr/local/lib/python3.10/site-packages/rest_framework/relations.py", line 153, in run_validation
    return super().run_validation(data)
  File "/usr/local/lib/python3.10/site-packages/rest_framework/fields.py", line 547, in run_validation
    value = self.to_internal_value(data)
  File "/usr/local/lib/python3.10/site-packages/rest_framework/relations.py", line 264, in to_internal_value
    return queryset.get(pk=data)
  File "/usr/local/lib/python3.10/site-packages/django/db/models/query.py", line 633, in get
    num = len(clone)
  File "/usr/local/lib/python3.10/site-packages/django/db/models/query.py", line 380, in __len__
    self._fetch_all()
  File "/usr/local/lib/python3.10/site-packages/django/db/models/query.py", line 1881, in _fetch_all
    self._result_cache = list(self._iterable_class(self))
  File "/usr/local/lib/python3.10/site-packages/django/db/models/query.py", line 91, in __iter__
    results = compiler.execute_sql(
  File "/usr/local/lib/python3.10/site-packages/django/db/models/sql/compiler.py", line 1562, in execute_sql
    cursor.execute(sql, params)
  File "/usr/local/lib/python3.10/site-packages/django/db/backends/utils.py", line 102, in execute
    return super().execute(sql, params)
  File "/usr/local/lib/python3.10/site-packages/django/db/backends/utils.py", line 67, in execute
    return self._execute_with_wrappers(
  File "/usr/local/lib/python3.10/site-packages/django/db/backends/utils.py", line 80, in _execute_with_wrappers
    return executor(sql, params, many, context)
  File "/usr/local/lib/python3.10/site-packages/django/db/backends/utils.py", line 84, in _execute
    with self.db.wrap_database_errors:
  File "/usr/local/lib/python3.10/site-packages/django/db/utils.py", line 91, in __exit__
    raise dj_exc_value.with_traceback(traceback) from exc_value
  File "/usr/local/lib/python3.10/site-packages/django/db/backends/utils.py", line 89, in _execute
    return self.cursor.execute(sql, params)
django.db.utils.OperationalError: server closed the connection unexpectedly
	This probably means the server terminated abnormally
	before or while processing the request.

Failed to complete cronjob at ('0 * * * *', 'api.crm.cron.main', '>> /code/api/log/debug7.log 2>&1 ')
Traceback (most recent call last):
  File "/usr/local/lib/python3.10/site-packages/django/db/backends/utils.py", line 89, in _execute
    return self.cursor.execute(sql, params)
psycopg2.OperationalError: server closed the connection unexpectedly
	This probably means the server terminated abnormally
	before or while processing the request.


The above exception was the direct cause of the following exception:

Traceback (most recent call last):
  File "/usr/local/lib/python3.10/site-packages/django_crontab/crontab.py", line 145, in run_job
    func(*job_args, **job_kwargs)
  File "/code/api/crm/cron.py", line 131, in main
    get_novus_and_save_in_api()
  File "/code/api/crm/cron.py", line 72, in get_novus_and_save_in_api
    response["total"] = parser_total(
  File "/code/api/crm/cron.py", line 15, in parser_total
    old_data = InteractionDetail.objects.filter(profile_client=profile["id"]).first()
  File "/usr/local/lib/python3.10/site-packages/django/db/models/query.py", line 1057, in first
    for obj in queryset[:1]:
  File "/usr/local/lib/python3.10/site-packages/django/db/models/query.py", line 398, in __iter__
    self._fetch_all()
  File "/usr/local/lib/python3.10/site-packages/django/db/models/query.py", line 1881, in _fetch_all
    self._result_cache = list(self._iterable_class(self))
  File "/usr/local/lib/python3.10/site-packages/django/db/models/query.py", line 91, in __iter__
    results = compiler.execute_sql(
  File "/usr/local/lib/python3.10/site-packages/django/db/models/sql/compiler.py", line 1562, in execute_sql
    cursor.execute(sql, params)
  File "/usr/local/lib/python3.10/site-packages/django/db/backends/utils.py", line 102, in execute
    return super().execute(sql, params)
  File "/usr/local/lib/python3.10/site-packages/django/db/backends/utils.py", line 67, in execute
    return self._execute_with_wrappers(
  File "/usr/local/lib/python3.10/site-packages/django/db/backends/utils.py", line 80, in _execute_with_wrappers
    return executor(sql, params, many, context)
  File "/usr/local/lib/python3.10/site-packages/django/db/backends/utils.py", line 84, in _execute
    with self.db.wrap_database_errors:
  File "/usr/local/lib/python3.10/site-packages/django/db/utils.py", line 91, in __exit__
    raise dj_exc_value.with_traceback(traceback) from exc_value
  File "/usr/local/lib/python3.10/site-packages/django/db/backends/utils.py", line 89, in _execute
    return self.cursor.execute(sql, params)
django.db.utils.OperationalError: server closed the connection unexpectedly
	This probably means the server terminated abnormally
	before or while processing the request.

Failed to complete cronjob at ('0 * * * *', 'api.crm.cron.main', '>> /code/api/log/debug7.log 2>&1 ')
Traceback (most recent call last):
  File "/usr/local/lib/python3.10/site-packages/urllib3/connection.py", line 198, in _new_conn
    sock = connection.create_connection(
  File "/usr/local/lib/python3.10/site-packages/urllib3/util/connection.py", line 85, in create_connection
    raise err
  File "/usr/local/lib/python3.10/site-packages/urllib3/util/connection.py", line 73, in create_connection
    sock.connect(sa)
TimeoutError: [Errno 110] Connection timed out

The above exception was the direct cause of the following exception:

Traceback (most recent call last):
  File "/usr/local/lib/python3.10/site-packages/urllib3/connectionpool.py", line 793, in urlopen
    response = self._make_request(
  File "/usr/local/lib/python3.10/site-packages/urllib3/connectionpool.py", line 491, in _make_request
    raise new_e
  File "/usr/local/lib/python3.10/site-packages/urllib3/connectionpool.py", line 467, in _make_request
    self._validate_conn(conn)
  File "/usr/local/lib/python3.10/site-packages/urllib3/connectionpool.py", line 1099, in _validate_conn
    conn.connect()
  File "/usr/local/lib/python3.10/site-packages/urllib3/connection.py", line 616, in connect
    self.sock = sock = self._new_conn()
  File "/usr/local/lib/python3.10/site-packages/urllib3/connection.py", line 207, in _new_conn
    raise ConnectTimeoutError(
urllib3.exceptions.ConnectTimeoutError: (<urllib3.connection.HTTPSConnection object at 0x7f296e1f98a0>, 'Connection to api.tago.io timed out. (connect timeout=None)')

The above exception was the direct cause of the following exception:

Traceback (most recent call last):
  File "/usr/local/lib/python3.10/site-packages/requests/adapters.py", line 486, in send
    resp = conn.urlopen(
  File "/usr/local/lib/python3.10/site-packages/urllib3/connectionpool.py", line 847, in urlopen
    retries = retries.increment(
  File "/usr/local/lib/python3.10/site-packages/urllib3/util/retry.py", line 515, in increment
    raise MaxRetryError(_pool, url, reason) from reason  # type: ignore[arg-type]
urllib3.exceptions.MaxRetryError: HTTPSConnectionPool(host='api.tago.io', port=443): Max retries exceeded with url: /data/?variable=3grecdi1va&query=last_item (Caused by ConnectTimeoutError(<urllib3.connection.HTTPSConnection object at 0x7f296e1f98a0>, 'Connection to api.tago.io timed out. (connect timeout=None)'))

During handling of the above exception, another exception occurred:

Traceback (most recent call last):
  File "/usr/local/lib/python3.10/site-packages/django_crontab/crontab.py", line 145, in run_job
    func(*job_args, **job_kwargs)
  File "/code/api/crm/cron.py", line 131, in main
    get_novus_and_save_in_api()
  File "/code/api/crm/cron.py", line 53, in get_novus_and_save_in_api
    request = requests.get(parsed_url, headers={
  File "/usr/local/lib/python3.10/site-packages/requests/api.py", line 73, in get
    return request("get", url, params=params, **kwargs)
  File "/usr/local/lib/python3.10/site-packages/requests/api.py", line 59, in request
    return session.request(method=method, url=url, **kwargs)
  File "/usr/local/lib/python3.10/site-packages/requests/sessions.py", line 589, in request
    resp = self.send(prep, **send_kwargs)
  File "/usr/local/lib/python3.10/site-packages/requests/sessions.py", line 703, in send
    r = adapter.send(request, **kwargs)
  File "/usr/local/lib/python3.10/site-packages/requests/adapters.py", line 507, in send
    raise ConnectTimeout(e, request=request)
requests.exceptions.ConnectTimeout: HTTPSConnectionPool(host='api.tago.io', port=443): Max retries exceeded with url: /data/?variable=3grecdi1va&query=last_item (Caused by ConnectTimeoutError(<urllib3.connection.HTTPSConnection object at 0x7f296e1f98a0>, 'Connection to api.tago.io timed out. (connect timeout=None)'))
